<?xml version="1.0"?>
<robot name="upper_body">

     <material name="red">
    <color rgba="0.8 0.0 0.0 0.5 "/>
  </material>
  <material name="green">
    <color rgba="0.0 0.8 0.0 0.5 "/>
  </material>


	<!-- Base Frame of Car -->
	<link name="body_link">
		<visual>
			<geometry>
				<box size="0.5 0.1 0.5"/>
			</geometry>
		</visual>
	</link>



<!-- HEAD  -->
	<link name="head_link">
		<visual>
			<geometry>
				<sphere radius="0.10"/>
			</geometry>
		</visual>
	</link>

	<joint name="fix_head_joint" type="fixed">
		<parent link="body_link"/>
		<child link="head_link"/>
		<origin rpy="0.0 0.0 0.0" xyz="0.0 0 0.32"/>
	</joint>

<!-- LEFT ARM -->

	<link name="left_shoulder">
		<visual>
			<geometry>
				<sphere radius="0.05"/>
			</geometry>
		</visual>
	</link>

	<joint name="left_fix_shoulder_joint" type="fixed">
		<parent link="body_link"/>
		<child link="left_shoulder"/>
		<origin rpy="0.0 0.0 0.0" xyz="0.25 -0.05 0.25"/>
	</joint>

	<link name="left_upper_arm">
		<visual>
			<geometry>
				<cylinder length="0.25" radius="0.03"/>
			</geometry>
		</visual>
	</link>


	<joint name="LShoulderX" type="continuous" >
	    <parent link="left_shoulder" />
	    <child link="left_shoulder_psi_link" />
	    <axis xyz="1 0 0" />
	    <dynamics damping="0.005" />
	</joint>

	<link name="left_shoulder_psi_link" />

	<joint name="LShoulderY" type="continuous" >
	    <parent link="left_shoulder_psi_link"/>
	    <child link="left_shoulder_theta_link"/>
	    <axis xyz="0 1 0" />
	    <dynamics damping="0.005" />
	</joint>

	<link name="left_shoulder_theta_link" />

	<joint name="LShoulderZ" type="continuous" >
	    <parent link="left_shoulder_theta_link"/>
	    <child link="left_shoulder3"/>
	    <axis xyz="0 0 1" />
	    <dynamics damping="0.005" />
	</joint>

	<link name="left_shoulder3"/>
	<joint name="left_should_fixed3" type="fixed" >
	    <parent link="left_shoulder3"/>
	    <child link="left_upper_arm"/>
	    <origin rpy="0 1.57 0" xyz="0.125 0 0.0"/>
	    <dynamics damping="0.005" />
	</joint>


<!--  -->

	<link name="left_elbow">
		<visual>
			<geometry>
				<sphere radius="0.05"/>
			</geometry>
		</visual>
	</link>

	<joint name="left_fix_elbow_joint" type="fixed">
		<parent link="left_upper_arm"/>
		<child link="left_elbow"/>
		<origin rpy="0.0 -1.57 0.0" xyz="0 0.0 0.125"/>
	</joint>


	<link name="left_lower_arm">
		<visual>
			<geometry>
				<cylinder length="0.25" radius="0.02"/>
			</geometry>
		</visual>
	</link>

	<joint name="LElbowX" type="continuous" >
	    <parent link="left_elbow" />
	    <child link="left_elbow_psi_link" />
	    <axis xyz="1 0 0" />
	    <dynamics damping="0.005" />
	</joint>

	<link name="left_elbow_psi_link" />

	<joint name="LElbowY" type="continuous" >
	    <parent link="left_elbow_psi_link"/>
	    <child link="left_elbow_theta_link"/>
	    <axis xyz="0 1 0" />
	    <dynamics damping="0.005" />
	</joint>

	<link name="left_elbow_theta_link" />

	<joint name="LElbowZ" type="continuous" >
	    <parent link="left_elbow_theta_link"/>
	    <child link="left_elbow3"/>
	    <axis xyz="0 0 1" />
	    <dynamics damping="0.005" />
	</joint>


	<link name="left_elbow3"/>
	<joint name="left_elbow_fixed3" type="fixed" >
	    <parent link="left_elbow3"/>
	    <child link="left_lower_arm"/>
	    <origin rpy="0 1.57 0.0" xyz="0.125 0 0"/>
	    <dynamics damping="0.005" />
	</joint>


	<link name="left_hand">
		<visual>
			<geometry>
				<sphere radius="0.05"/>
			</geometry>
		<material name="red"/>
		</visual>
	</link>
	<joint name="left_hand_fixed" type="fixed" >
	    <parent link="left_lower_arm"/>
	    <child link="left_hand"/>
	    <origin rpy="0 -1.57 0.0" xyz="0 0 0.125"/>
	    <dynamics damping="0.005" />
	</joint>




<!-- RIGHT ARM -->

	<link name="right_shoulder">
		<visual>
			<geometry>
				<sphere radius="0.05"/>
			</geometry>
		</visual>
	</link>

	<joint name="right_fix_shoulder_joint" type="fixed">
		<parent link="body_link"/>
		<child link="right_shoulder"/>
		<origin rpy="-3.1415926 0.0 0.0" xyz="-0.25 -0.05 0.25"/>
	</joint>

	<link name="right_upper_arm">
		<visual>
			<geometry>
				<cylinder length="0.25" radius="0.03"/>
			</geometry>
		</visual>
	</link>


	<joint name="RShoulderX" type="continuous" >
	    <parent link="right_shoulder" />
	    <child link="right_shoulder_psi_link" />
	    <axis xyz="1 0 0" />
	    <dynamics damping="0.005" />
	</joint>

	<link name="right_shoulder_psi_link" />

	<joint name="RShoulderY" type="continuous" >
	    <parent link="right_shoulder_psi_link"/>
	    <child link="right_shoulder_theta_link"/>
	    <axis xyz="0 1 0" />
	    <dynamics damping="0.005" />
	</joint>

	<link name="right_shoulder_theta_link" />

	<joint name="RShoulderZ" type="continuous" >
	    <parent link="right_shoulder_theta_link"/>
	    <child link="right_shoulder3"/>
	    <axis xyz="0 0 1" />
	    <dynamics damping="0.005" />
	</joint>

	<link name="right_shoulder3"/>
	<joint name="right_should_fixed3" type="fixed" >
	    <parent link="right_shoulder3"/>
	    <child link="right_upper_arm"/>
	    <origin rpy="0 1.57 0" xyz="-0.125 0 0.0"/>
	    <dynamics damping="0.005" />
	</joint>


<!--  -->

	<link name="right_elbow">
		<visual>
			<geometry>
				<sphere radius="0.05"/>
			</geometry>
		</visual>
	</link>

	<joint name="right_fix_elbow_joint" type="fixed">
		<parent link="right_upper_arm"/>
		<child link="right_elbow"/>
		<origin rpy="0.0 -1.57 0.0" xyz="0 0.0 -0.125"/>
	</joint>


	<link name="right_lower_arm">
		<visual>
			<geometry>
				<cylinder length="0.25" radius="0.02"/>
			</geometry>
		</visual>
	</link>

	<joint name="RElbowX" type="continuous" >
	    <parent link="right_elbow" />
	    <child link="right_elbow_psi_link" />
	    <axis xyz="1 0 0" />
	    <dynamics damping="0.005" />
	</joint>

	<link name="right_elbow_psi_link" />

	<joint name="RElbowY" type="continuous" >
	    <parent link="right_elbow_psi_link"/>
	    <child link="right_elbow_theta_link"/>
	    <axis xyz="0 1 0" />
	    <dynamics damping="0.005" />
	</joint>

	<link name="right_elbow_theta_link" />

	<joint name="RElbowZ" type="continuous" >
	    <parent link="right_elbow_theta_link"/>
	    <child link="right_elbow3"/>
	    <axis xyz="0 0 1" />
	    <dynamics damping="0.005" />
	</joint>


	<link name="right_elbow3"/>
	<joint name="right_elbow_fixed3" type="fixed" >
	    <parent link="right_elbow3"/>
	    <child link="right_lower_arm"/>
	    <origin rpy="0 1.57 0.0" xyz="-0.125 0 0"/>
	    <dynamics damping="0.005" />
	</joint>


	<link name="right_hand">
		<visual>
			<geometry>
				<sphere radius="0.05"/>
			</geometry>
		<material name="green"/>
		</visual>
	</link>
	<joint name="right_hand_fixed" type="fixed" >
	    <parent link="right_lower_arm"/>
	    <child link="right_hand"/>
	    <origin rpy="0 -1.57 0.0" xyz="0 0 -0.125"/>
	    <dynamics damping="0.005" />
	</joint>





</robot>