<?xml version="1.0"?>
<robot name="upper_body">

     <material name="red">
    <color rgba="0.8 0.0 0.0 0.5 "/>
  </material>
  <material name="green">
    <color rgba="0.0 0.8 0.0 0.5 "/>
  </material>


	<!-- Base Frame of Car -->
	<link name="world"/>


	<link name="SpineBase">
		<visual>
			<geometry>
				<sphere radius="0.05"/>
			</geometry>
		</visual>
	</link>


	<joint name="base_spine_joint" type="fixed">
		<parent link="world"/>
		<child link="SpineBase"/>
		<origin rpy="0 0 0" xyz="0 0 0"/>
	</joint>


	<link name="SpineLink">
		<visual>
			<geometry>
				<cylinder radius="0.05" length="0.4"/>
			</geometry>
		</visual>
	</link>




	<joint name="spine_joint" type="fixed">
		<parent link="SpineBase"/>
		<child link="SpineLink"/>
		<origin rpy="1.57 0 0.0" xyz="0 0.2 0"/>
	</joint>



	<joint name="shoulder_spine_joint" type="fixed">
		<parent link="SpineLink"/>
		<child link="shoulder_spine_link"/>
		<origin rpy="-1.57 0 0.0" xyz="0 0 -0.2"/>
	</joint>


	<link name="shoulder_spine_link">
		<visual>
			<geometry>
				<sphere radius="0.05"/>
			</geometry>
		</visual>
	</link>

	<link name="left_spine_theta_link" />

	<joint name="ShoulderSY" type="continuous">
		<parent link="shoulder_spine_link"/>
		<child link="left_spine_theta_link" />
		<axis xyz="0 1 0"/>
		<dynamics damping="0.005" />
	</joint>

	
	<link name="left_spine_phi_link" />
	<joint name="ShoulderSZ" type="continuous">
		<parent link="left_spine_theta_link"/>
		<child link="left_spine_phi_link" />
		<axis xyz="0 0 1"/>
		<dynamics damping="0.005" />
	</joint>

	
	<joint name="Shoulder_fixed" type="fixed">
		<parent link="left_spine_phi_link"/>
		<child link="left_spine_to_shoulde_link" />
		<origin rpy="0 1.57 0" xyz="0.08 0 0"/>
		
	</joint>	


	<link name="left_spine_to_shoulde_link">
		<visual>
			<geometry>
				<cylinder radius="0.02" length="0.16"/>
			</geometry>
		</visual>
	</link>


	<link name="left_shoulder_link">
		<visual>
			<geometry>
				<sphere radius="0.02"/>
			</geometry>
		</visual>
	</link>

	<joint name="LShoulderX" type="continuous">
		<parent link="left_spine_to_shoulde_link"/>
		<child link="left_shoulder_link"/>
		<axis xyz="1 0 0" />
		<origin rpy="1.57 0 -1.57" xyz="0 0 0.08"/>
	</joint>


	<link name="left_shoulder_theta_link" />
	<joint name="LShoulderY" type="continuous" >
	    <parent link="left_shoulder_link"/>
	    <child link="left_shoulder_theta_link"/>
	    <axis xyz="0 1 0" />
	    <dynamics damping="0.005" />
	</joint>


	<joint name="LShoulderZ" type="continuous" >
	    <parent link="left_shoulder_theta_link"/>
	    <child link="ShoulderLeft"/>
	    <axis xyz="0 0 1" />
	    <dynamics damping="0.005" />
	</joint>

	<link name="ShoulderLeft"/>
	<link name="left_upper_arm">
		<visual>
			<geometry>
				<cylinder length="0.24" radius="0.03"/>
			</geometry>
		</visual>
	</link>
	<joint name="left_should_fixed" type="fixed" >
	    <parent link="ShoulderLeft"/>
	    <child link="left_upper_arm"/>
	    <origin rpy="0 1.57 0" xyz="0.12 0 0.0"/>
	    <dynamics damping="0.005" />
	</joint>


<!-- elbow -->
	<link name="left_elbow">
		<visual>
			<geometry>
				<sphere radius="0.02"/>
			</geometry>
		</visual>
	</link>

	<joint name="left_fix_elbow_joint" type="fixed">
		<parent link="left_upper_arm"/>
		<child link="left_elbow"/>
		<origin rpy="1.57 0 3.14" xyz="0 0.0 0.12"/>
	</joint>


	<link name="left_lower_arm">
		<visual>
			<geometry>
				<cylinder length="0.28" radius="0.02"/>
			</geometry>
		</visual>
	</link>

	<joint name="LElbowX" type="continuous" >
	    <parent link="left_elbow" />
	    <child link="left_elbow_psi_link" />
	    <axis xyz="1 0 0" />
	    <dynamics damping="0.005" />
	</joint>

	<link name="left_elbow_psi_link" />

	<joint name="LElbowY" type="continuous" >
	    <parent link="left_elbow_psi_link"/>
	    <child link="left_elbow_theta_link"/>
	    <axis xyz="0 1 0" />
	    <dynamics damping="0.005" />
	</joint>

	<link name="left_elbow_theta_link" />

	<joint name="LElbowZ" type="continuous" >
	    <parent link="left_elbow_theta_link"/>
	    <child link="ElbowLeft"/>
	    <axis xyz="0 0 1" />
	    <dynamics damping="0.005" />
	</joint>


	<link name="ElbowLeft"/>
	<joint name="left_elbow_fixed3" type="fixed" >
	    <parent link="ElbowLeft"/>
	    <child link="left_lower_arm"/>
	    <origin rpy="1.57 0 0.0" xyz="0 0.12 0"/>
	    <dynamics damping="0.005" />
	</joint>

	<link name="left_hand">
		<visual>
			<geometry>
				<sphere radius="0.05"/>
			</geometry>
		<material name="red"/>
		</visual>
	</link>
	<joint name="left_hand_fixed" type="fixed" >
	    <parent link="left_lower_arm"/>
	    <child link="left_hand"/>
	    <origin rpy="0 0 0.0" xyz="0 0 -0.12"/>
	    <dynamics damping="0.005" />
	</joint>



<!-- HEAD  -->
<!-- 	<link name="head_link">
		<visual>
			<geometry>
				<sphere radius="0.10"/>
			</geometry>
		</visual>
	</link>

	<joint name="fix_head_joint" type="fixed">
		<parent link="body_link"/>
		<child link="head_link"/>
		<origin rpy="0.0 0.0 0.0" xyz="0.0 0 0.32"/>
	</joint> -->

<!-- LEFT ARM -->

<!-- 	<link name="left_shoulder">
		<visual>
			<geometry>
				<sphere radius="0.05"/>
			</geometry>
		</visual>
	</link>

	<joint name="left_fix_shoulder_joint" type="fixed">
		<parent link="body_link"/>
		<child link="shoulder_spine_link"/>
		<origin rpy="1.57 0 0.0" xyz="0.25 -0.05 0.25"/>
	</joint>

	<link name="left_upper_arm">
		<visual>
			<geometry>
				<cylinder length="0.25" radius="0.03"/>
			</geometry>
		</visual>
	</link>


	<joint name="LShoulderX" type="continuous" >
	    <parent link="left_shoulder" />
	    <child link="left_shoulder_psi_link" />
	    <axis xyz="1 0 0" />
	    <dynamics damping="0.005" />
	</joint>

	<link name="left_shoulder_psi_link" />

	<joint name="LShoulderY" type="continuous" >
	    <parent link="left_shoulder_psi_link"/>
	    <child link="left_shoulder_theta_link"/>
	    <axis xyz="0 1 0" />
	    <dynamics damping="0.005" />
	</joint>

	<link name="left_shoulder_theta_link" />

	<joint name="LShoulderZ" type="continuous" >
	    <parent link="left_shoulder_theta_link"/>
	    <child link="left_shoulder3"/>
	    <axis xyz="0 0 1" />
	    <dynamics damping="0.005" />
	</joint>

	<link name="left_shoulder3"/>
	<joint name="left_should_fixed3" type="fixed" >
	    <parent link="left_shoulder3"/>
	    <child link="left_upper_arm"/>
	    <origin rpy="0 1.57 0" xyz="0.125 0 0.0"/>
	    <dynamics damping="0.005" />
	</joint> -->


<!--  -->

<!-- 	<link name="left_elbow">
		<visual>
			<geometry>
				<sphere radius="0.05"/>
			</geometry>
		</visual>
	</link>

	<joint name="left_fix_elbow_joint" type="fixed">
		<parent link="left_upper_arm"/>
		<child link="left_elbow"/>
		<origin rpy="0 0 0" xyz="0 0.0 0.125"/>
	</joint>


	<link name="left_lower_arm">
		<visual>
			<geometry>
				<cylinder length="0.25" radius="0.02"/>
			</geometry>
		</visual>
	</link>

	<joint name="LElbowX" type="continuous" >
	    <parent link="left_elbow" />
	    <child link="left_elbow_psi_link" />
	    <axis xyz="1 0 0" />
	    <dynamics damping="0.005" />
	</joint>

	<link name="left_elbow_psi_link" />

	<joint name="LElbowY" type="continuous" >
	    <parent link="left_elbow_psi_link"/>
	    <child link="left_elbow_theta_link"/>
	    <axis xyz="0 1 0" />
	    <dynamics damping="0.005" />
	</joint>

	<link name="left_elbow_theta_link" />

	<joint name="LElbowZ" type="continuous" >
	    <parent link="left_elbow_theta_link"/>
	    <child link="left_elbow3"/>
	    <axis xyz="0 0 1" />
	    <dynamics damping="0.005" />
	</joint>


	<link name="left_elbow3"/>
	<joint name="left_elbow_fixed3" type="fixed" >
	    <parent link="left_elbow3"/>
	    <child link="left_lower_arm"/>
	    <origin rpy="1.57 0 0.0" xyz="0 0.125 0"/>
	    <dynamics damping="0.005" />
	</joint>


	<link name="left_hand">
		<visual>
			<geometry>
				<sphere radius="0.05"/>
			</geometry>
		<material name="red"/>
		</visual>
	</link>
	<joint name="left_hand_fixed" type="fixed" >
	    <parent link="left_lower_arm"/>
	    <child link="left_hand"/>
	    <origin rpy="-1.57 0 0.0" xyz="0 0 -0.125"/>
	    <dynamics damping="0.005" />
	</joint>
 -->



<!-- RIGHT ARM -->
<!-- 
	<link name="right_shoulder">
		<visual>
			<geometry>
				<sphere radius="0.05"/>
			</geometry>
		</visual>
	</link>

	<joint name="right_fix_shoulder_joint" type="fixed">
		<parent link="body_link"/>
		<child link="right_shoulder"/>
		<origin rpy="1.57 -1.57 0.0" xyz="-0.25 -0.05 0.25"/>
	</joint>

	<link name="right_upper_arm">
		<visual>
			<geometry>
				<cylinder length="0.25" radius="0.03"/>
			</geometry>
		</visual>
	</link>


	<joint name="RShoulderX" type="continuous" >
	    <parent link="right_shoulder" />
	    <child link="right_shoulder_psi_link" />
	    <axis xyz="1 0 0" />
	    <dynamics damping="0.005" />
	</joint>

	<link name="right_shoulder_psi_link" />

	<joint name="RShoulderY" type="continuous" >
	    <parent link="right_shoulder_psi_link"/>
	    <child link="right_shoulder_theta_link"/>
	    <axis xyz="0 1 0" />
	    <dynamics damping="0.005" />
	</joint>

	<link name="right_shoulder_theta_link" />

	<joint name="RShoulderZ" type="continuous" >
	    <parent link="right_shoulder_theta_link"/>
	    <child link="right_shoulder3"/>
	    <axis xyz="0 0 1" />
	    <dynamics damping="0.005" />
	</joint>

	<link name="right_shoulder3"/>
	<joint name="right_should_fixed3" type="fixed" >
	    <parent link="right_shoulder3"/>
	    <child link="right_upper_arm"/>
	    <origin rpy="0 1.57 0" xyz="-0.125 0 0.0"/>
	    <dynamics damping="0.005" />
	</joint> -->


<!--  -->

<!-- 	<link name="right_elbow">
		<visual>
			<geometry>
				<sphere radius="0.05"/>
			</geometry>
		</visual>
	</link>

	<joint name="right_fix_elbow_joint" type="fixed">
		<parent link="right_upper_arm"/>
		<child link="right_elbow"/>
		<origin rpy="0.0 -1.57 0.0" xyz="0 0.0 -0.125"/>
	</joint>


	<link name="right_lower_arm">
		<visual>
			<geometry>
				<cylinder length="0.25" radius="0.02"/>
			</geometry>
		</visual>
	</link>

	<joint name="RElbowX" type="continuous" >
	    <parent link="right_elbow" />
	    <child link="right_elbow_psi_link" />
	    <axis xyz="1 0 0" />
	    <dynamics damping="0.005" />
	</joint>

	<link name="right_elbow_psi_link" />

	<joint name="RElbowY" type="continuous" >
	    <parent link="right_elbow_psi_link"/>
	    <child link="right_elbow_theta_link"/>
	    <axis xyz="0 1 0" />
	    <dynamics damping="0.005" />
	</joint>

	<link name="right_elbow_theta_link" />

	<joint name="RElbowZ" type="continuous" >
	    <parent link="right_elbow_theta_link"/>
	    <child link="right_elbow3"/>
	    <axis xyz="0 0 1" />
	    <dynamics damping="0.005" />
	</joint>


	<link name="right_elbow3"/>
	<joint name="right_elbow_fixed3" type="fixed" >
	    <parent link="right_elbow3"/>
	    <child link="right_lower_arm"/>
	    <origin rpy="0 1.57 0.0" xyz="-0.125 0 0"/>
	    <dynamics damping="0.005" />
	</joint>


	<link name="right_hand">
		<visual>
			<geometry>
				<sphere radius="0.05"/>
			</geometry>
		<material name="green"/>
		</visual>
	</link>
	<joint name="right_hand_fixed" type="fixed" >
	    <parent link="right_lower_arm"/>
	    <child link="right_hand"/>
	    <origin rpy="0 -1.57 0.0" xyz="0 0 -0.125"/>
	    <dynamics damping="0.005" />
	</joint>
 -->




</robot>